test_build_recursive_sequence_generator (__main__.TestExercice) ... FAIL
test_fibonacci_number (__main__.TestExercice) ... FAIL
test_get_fibonacci_number (__main__.TestExercice) ... ok
test_get_fibonacci_sequence (__main__.TestExercice) ... ok
test_get_sorted_dict_by_decimals (__main__.TestExercice) ... ok

======================================================================
FAIL: test_build_recursive_sequence_generator (__main__.TestExercice)
----------------------------------------------------------------------
Traceback (most recent call last):
  File "c:\Users\youne\Documents\GitHub\2021a_c03_ch7_1_exercices-Younes51-1\test_exercice.py", line 80, in test_build_recursive_sequence_generator
    fibo = build_recursive_sequence_generator([0, 1], fibo_def, False)
TypeError: build_recursive_sequence_generator() takes 1 positional argument but 3 were given

During handling of the above exception, another exception occurred:

Traceback (most recent call last):
  File "c:\Users\youne\Documents\GitHub\2021a_c03_ch7_1_exercices-Younes51-1\test_exercice.py", line 82, in test_build_recursive_sequence_generator
    self.fail("l'appel échoue")
AssertionError: l'appel échoue

======================================================================
FAIL: test_fibonacci_number (__main__.TestExercice)
----------------------------------------------------------------------
Traceback (most recent call last):
  File "c:\Users\youne\Documents\GitHub\2021a_c03_ch7_1_exercices-Younes51-1\test_exercice.py", line 70, in test_fibonacci_number
    self.assertListEqual(
AssertionError: Lists differ: ['0, 1, 1, 2, 3, 5, 8, 13, 21, 34'] != [0, 1, 1, 2, 3, 5, 8, 13, 21, 34]

First differing element 0:
'0, 1, 1, 2, 3, 5, 8, 13, 21, 34'
0

Second list contains 9 additional elements.
First extra element 1:
1

- ['0, 1, 1, 2, 3, 5, 8, 13, 21, 34']
?  -                               -

+ [0, 1, 1, 2, 3, 5, 8, 13, 21, 34]

----------------------------------------------------------------------
Ran 5 tests in 0.001s

FAILED (failures=2)
